Workbook
Name n_1: {"","одинz","дваz","триz","четыреz","пятьz","шестьz","семьz","восемьz","девятьz"}
Name n_1: {"","одинz","дваz","триz","четыреz","пятьz","шестьz","семьz","восемьz","девятьz"}
Name n_1: {"","одинz","дваz","триz","четыреz","пятьz","шестьz","семьz","восемьz","девятьz"}
Name n_1: {"","одинz","дваz","триz","четыреz","пятьz","шестьz","семьz","восемьz","девятьz"}
Name n_1: {"","одинz","дваz","триz","четыреz","пятьz","шестьz","семьz","восемьz","девятьz"}
Name n_1: {"","одинz","дваz","триz","четыреz","пятьz","шестьz","семьz","восемьz","девятьz"}
Name n_2: {"десятьz","одиннадцатьz","двенадцатьz","тринадцатьz","четырнадцатьz","пятнадцатьz","шестнадцатьz","семнадцатьz","восемнадцатьz","девятнадцатьz"}
Name n_2: {"десятьz","одиннадцатьz","двенадцатьz","тринадцатьz","четырнадцатьz","пятнадцатьz","шестнадцатьz","семнадцатьz","восемнадцатьz","девятнадцатьz"}
Name n_2: {"десятьz","одиннадцатьz","двенадцатьz","тринадцатьz","четырнадцатьz","пятнадцатьz","шестнадцатьz","семнадцатьz","восемнадцатьz","девятнадцатьz"}
Name n_2: {"десятьz","одиннадцатьz","двенадцатьz","тринадцатьz","четырнадцатьz","пятнадцатьz","шестнадцатьz","семнадцатьz","восемнадцатьz","девятнадцатьz"}
Name n_2: {"десятьz","одиннадцатьz","двенадцатьz","тринадцатьz","четырнадцатьz","пятнадцатьz","шестнадцатьz","семнадцатьz","восемнадцатьz","девятнадцатьz"}
Name n_2: {"десятьz","одиннадцатьz","двенадцатьz","тринадцатьz","четырнадцатьz","пятнадцатьz","шестнадцатьz","семнадцатьz","восемнадцатьz","девятнадцатьz"}
Name n_3: {"";1;"двадцатьz";"тридцатьz";"сорокz";"пятьдесятz";"шестьдесятz";"семьдесятz";"восемьдесятz";"девяностоz"}
Name n_3: {"";1;"двадцатьz";"тридцатьz";"сорокz";"пятьдесятz";"шестьдесятz";"семьдесятz";"восемьдесятz";"девяностоz"}
Name n_3: {"";1;"двадцатьz";"тридцатьz";"сорокz";"пятьдесятz";"шестьдесятz";"семьдесятz";"восемьдесятz";"девяностоz"}
Name n_3: {"";1;"двадцатьz";"тридцатьz";"сорокz";"пятьдесятz";"шестьдесятz";"семьдесятz";"восемьдесятz";"девяностоz"}
Name n_3: {"";1;"двадцатьz";"тридцатьz";"сорокz";"пятьдесятz";"шестьдесятz";"семьдесятz";"восемьдесятz";"девяностоz"}
Name n_3: {"";1;"двадцатьz";"тридцатьz";"сорокz";"пятьдесятz";"шестьдесятz";"семьдесятz";"восемьдесятz";"девяностоz"}
Name n_4: {"","стоz","двестиz","тристаz","четырестаz","пятьсотz","шестьсотz","семьсотz","восемьсотz","девятьсотz"}
Name n_4: {"","стоz","двестиz","тристаz","четырестаz","пятьсотz","шестьсотz","семьсотz","восемьсотz","девятьсотz"}
Name n_4: {"","стоz","двестиz","тристаz","четырестаz","пятьсотz","шестьсотz","семьсотz","восемьсотz","девятьсотz"}
Name n_4: {"","стоz","двестиz","тристаz","четырестаz","пятьсотz","шестьсотz","семьсотz","восемьсотz","девятьсотz"}
Name n_4: {"","стоz","двестиz","тристаz","четырестаz","пятьсотz","шестьсотz","семьсотz","восемьсотz","девятьсотz"}
Name n_4: {"","стоz","двестиz","тристаz","четырестаz","пятьсотz","шестьсотz","семьсотz","восемьсотz","девятьсотz"}
Name n_5: {"","однаz","двеz","триz","четыреz","пятьz","шестьz","семьz","восемьz","девятьz"}
Name n_5: {"","однаz","двеz","триz","четыреz","пятьz","шестьz","семьz","восемьz","девятьz"}
Name n_5: {"","однаz","двеz","триz","четыреz","пятьz","шестьz","семьz","восемьz","девятьz"}
Name n_5: {"","однаz","двеz","триz","четыреz","пятьz","шестьz","семьz","восемьz","девятьz"}
Name n_5: {"","однаz","двеz","триz","четыреz","пятьz","шестьz","семьz","восемьz","девятьz"}
Name n_5: {"","однаz","двеz","триz","четыреz","пятьz","шестьz","семьz","восемьz","девятьz"}
Name n0: "000000000000"&MID(1/2,2,1)&"00"
Name n0x: IF('Акт невозврата Вышки'!n_3=1,'Акт невозврата Вышки'!n_2,'Акт невозврата Вышки'!n_3&'Акт невозврата Вышки'!n_1)
Name n0x: IF('Акт невозврата Леса'!n_3=1,'Акт невозврата Леса'!n_2,'Акт невозврата Леса'!n_3&'Акт невозврата Леса'!n_1)
Name n0x: IF(ДляДоговора!n_3=1,ДляДоговора!n_2,ДляДоговора!n_3&ДляДоговора!n_1)
Name n0x: IF(n_3=1,n_2,n_3&n_1)
Name n0x: IF(n_3=1,n_2,n_3&n_1)
Name n0x: IF(n_3=1,n_2,n_3&n_1)
Name n1x: IF('Акт невозврата Вышки'!n_3=1,'Акт невозврата Вышки'!n_2,'Акт невозврата Вышки'!n_3&'Акт невозврата Вышки'!n_5)
Name n1x: IF('Акт невозврата Леса'!n_3=1,'Акт невозврата Леса'!n_2,'Акт невозврата Леса'!n_3&'Акт невозврата Леса'!n_5)
Name n1x: IF(ДляДоговора!n_3=1,ДляДоговора!n_2,ДляДоговора!n_3&ДляДоговора!n_5)
Name n1x: IF(n_3=1,n_2,n_3&n_5)
Name n1x: IF(n_3=1,n_2,n_3&n_5)
Name n1x: IF(n_3=1,n_2,n_3&n_5)
Name Договоры: '[1]Расчет лесов'!#REF!
Name Договоры: '[1]Расчет лесов'!#REF!
Name Договоры: '[1]Расчет лесов'!#REF!
Name Договоры: 'Расчет лесов'!#REF!
Name Договоры: 'Расчет лесов'!#REF!
Name мил: {0,"овz";1,"z";2,"аz";5,"овz"}
Name мил: {0,"овz";1,"z";2,"аz";5,"овz"}
Name мил: {0,"овz";1,"z";2,"аz";5,"овz"}
Name мил: {0,"овz";1,"z";2,"аz";5,"овz"}
Name мил: {0,"овz";1,"z";2,"аz";5,"овz"}
Name мил: {0,"овz";1,"z";2,"аz";5,"овz"}
Name тыс: {0,"тысячz";1,"тысячаz";2,"тысячиz";5,"тысячz"}
Name тыс: {0,"тысячz";1,"тысячаz";2,"тысячиz";5,"тысячz"}
Name тыс: {0,"тысячz";1,"тысячаz";2,"тысячиz";5,"тысячz"}
Name тыс: {0,"тысячz";1,"тысячаz";2,"тысячиz";5,"тысячz"}
Name тыс: {0,"тысячz";1,"тысячаz";2,"тысячиz";5,"тысячz"}
Name тыс: {0,"тысячz";1,"тысячаz";2,"тысячиz";5,"тысячz"}

Sheet Расчет лесов
A1: УПСК Аренда строительных лесов | B1: Параметры цен | I1: Параметры здания/стены | N1: Город= | O1: Екатеринбург | P1: к= | Q1: =IF(O1="Екатеринбург",AG22,IF(O1="Челябинск",AG23,IF(O1="Новосибирск",AG25,IF(O1="Пермь",AG24)))) -> 1 | Y1: Договор | Z1: НДС | AA1: Длина | AB1: Высота | AF1: Кол-во метров/ срок аренды | AG1: до 3х дней | AH1: До недели | AI1: До 2-х недель | AJ1: До месяца | AK1: До 45дн | AL1: До 2-х месяцев | AM1: Св 2 месяцев
B2: цена за м2 | C2: =IF(AND(C4<=7,L12<=50),AH2,IF(AND(C4<=14,L12<=50),AI2,IF(AND(C4<=30,L12<=50),AJ2,IF(AND(C4<=45,L12<=50),AK2,IF(AND(C4<=60,L12<=50),AL2,IF(AND(C4>60,L12<=50),AM2, IF(AND(C4<=7,L12<=100),AH3, IF(AND(C4<=14,L12<=100),AI3, IF(AND(C4<=30,L12<=100),AJ3,IF(AND(C4<=45,L12<=100),AK3, IF(AND(C4<=60,L12<=100),AL3, IF(AND(C4>60,L12<=100),AM3, IF(AND(C4<=7,L12<=300),AH4, IF(AND(C4<=14,L12<=300),AI4, IF(AND(C4<=30,L12<=300),AJ4,IF(AND(C4<=45,L12<=300),AK4, IF(AND(C4<=60,L12<=300),AL4, IF(AND(C4>60,L12<=300),AM4, IF(AND(C4<=7,L12<=500),AH5, IF(AND(C4<=14,L12<=500),AI5, IF(AND(C4<=30,L12<=500),AJ5,IF(AND(C4<=45,L12<=500),AK5, IF(AND(C4<=60,L12<=500),AL5, IF(AND(C4>60,L12<=500),AM5, IF(AND(C4<=7,L12<=1000),AH6, IF(AND(C4<=14,L12<=1000),AI6, IF(AND(C4<=30,L12<=1000),AJ6,IF(AND(C4<=45,L12<=1000),AK6, IF(AND(C4<=60,L12<=1000),AL6, IF(AND(C4>60,L12<=1000),AM6, IF(AND(C4<=7,L12>1000),AH7, IF(AND(C4<=14,L12>1000),AI7, IF(AND(C4<=30,L12>1000),AJ7, IF(AND(C4<=45,L12>1000),AK7, IF(AND(C4<=60,L12>1000),AL7, IF(AND(C4>60,L12>1000),AM7, "нету" ))))))))))))))))))))))))))))))))))))*Q1+Q21 -> 3.2 | D2: руб | J2: длинна | K2: высота | L2: ПЛОЩАДЬ | M2: проверка | N2: Доставка= | O2: 0 | Q2: Сезон дисконт | S2: 1.2 | T2: для юр | V2: =IF(B8=B9,1.7,1) -> 1.7 | Y2: Физ | Z2: без НДС | AA2: 0 | AB2: 0 | AE2: 1 | AF2: До 50м2 | AG2: 10 | AH2: 8 | AI2: 4.5 | AJ2: 3.2 | AK2: 2.5 | AL2: 2 | AM2: 1.6
B3: ст-ть аренды | C3: =ROUNDUP((C2*L12*S2*V2+L21*S2+Q22),-1) -> 210 | D3: в сутки | I3: Сторона1 | J3: 3 | K3: 8 | L3: =J3*K3 -> 24 | M3: =L3/3 -> 8 | N3: Погрузка= | O3: =AJ25*150 -> 300 | Q3: нал | R3: безнал | Y3: Юр | Z3: с НДС 20% | AA3: 3 | AB3: 2 | AE3: 2 | AF3: До 100м2 | AG3: 8 | AH3: 5 | AI3: 3.7 | AJ3: 2.7 | AK3: 2 | AL3: 1.65 | AM3: 1.4
B4: кол-во суток | C4: 30 | J4: =J3/3 -> 1 | K4: =K3/2 -> 4 | M4: =J4*K4 -> 4 | N4: Расстояние | O4: 50 | P4: км | Q4: =O4*2*O5 -> 1800 | R4: =Q4*1.18 -> 2124 | Y4: своё знач. | AA4: 6 | AB4: 4 | AE4: 3 | AF4: До 300м2 | AG4: 5 | AH4: 4 | AI4: 2.8 | AJ4: 2.1 | AK4: 1.7 | AL4: 1.45 | AM4: 1.25
B5: 1м2 стоит | C5: =ROUNDUP(D16/L12, 0) -> 1269 | D5: руб | I5: Сторона2 | J5: 0 | K5: 0 | L5: =J5*K5 -> 0 | M5: =L5/3 -> 0 | N5: Цена за км | O5: 18 | Z5: =IF(O9="без НДС",0,1) -> 1 | AA5: 9 | AB5: 6 | AE5: 4 | AF5: До 500м2 | AH5: 3 | AI5: 2 | AJ5: 1.65 | AK5: 1.5 | AL5: 1.3 | AM5: 1.1
J6: =J5/3 -> 0 | K6: =K5/2 -> 0 | M6: =J6*K6 -> 0 | N6: Договор | O6: своё знач. | P6: = | Q6: 10 | AA6: 12 | AB6: 8 | AE6: 5 | AF6: До 1000м2 | AH6: 2.5 | AI6: 1.7 | AJ6: 1.4 | AK6: 1.25 | AL6: 1.1 | AM6: 1
A7: Наименование | B7: Количество | C7: Стоимость | D7: Сумма, руб. | E7: % | I7: Сторона3 | J7: 0 | K7: 0 | L7: =J7*K7 -> 0 | M7: =L7/3 -> 0 | N7: Залог | O7: =Q6 -> 10 | P7: % | Y7: =IF(J3<=18,0,IF(J3<=39,0,0)) -> 0 | AA7: 15 | AB7: 10 | AE7: 6 | AF7: Св 1000м2 | AH7: 2 | AI7: 1.5 | AJ7: 1.25 | AK7: 1.1 | AL7: 1 | AM7: 0.9
A8: 1 Рама проходная ЛСПР-200 | B8: =(J16-J17)+(K16-K17)+(L16-L17)+(M16-M17)+(N16-N17) -> 4 | C8: =AI32 -> 1400 | D8: =B8*C8 -> 5600 | E8: =D8*100/$D$16 -> 18.396846 | F8: =$C$3/100*E8 -> 38.633377 | G8: =IF(B8=0,0,F8/B8) -> 9.6583443 | J8: =J7/3 -> 0 | K8: =K7/2 -> 0 | M8: =J8*K8 -> 0 | N8: Вес | O8: =AI24 -> 375.6 | P8: кг | Q8: Машин | R8: =O8/1400 -> 0.26828571 | AA8: 18 | AB8: 12
A9: 2 Рама с лестницей ЛСПР-200 | B9: =J17+K17+L17+M17+N17 -> 4 | C9: =AI33 -> 1670 | D9: =B9*C9 -> 6680 | E9: =D9*100/$D$16 -> 21.944809 | F9: =$C$3/100*E9 -> 46.0841 | G9: =IF(B9=0,0,F9/B9) -> 11.521025 | I9: Сторона4 | J9: 0 | K9: 0 | L9: =J9*K9 -> 0 | M9: =L9/3 -> 0 | N9: Объем | O9: =AJ24 -> 1.6848 | P9: м3 | Y9: =B8+B9 -> 8 | AA9: 21 | AB9: 14 | AE9: Подмости | AF9: шт (3м*1м) | AH9: 18 | AI9: 13 | AJ9: 10 | AK9: 8 | AL9: 7 | AM9: 5
A10: 3 Диагональная связь (3,3 м) ЛСПР-200 | B10: =J19+K19+L19+M19+N19 -> 4 | C10: =AI34 -> 630 | D10: =B10*C10 -> 2520 | E10: =D10*100/$D$16 -> 8.2785808 | F10: =$C$3/100*E10 -> 17.38502 | G10: =IF(B10=0,0,F10/B10) -> 4.3462549 | J10: =J9/3 -> 0 | K10: =K9/2 -> 0 | M10: =J10*K10 -> 0 | AA10: 24 | AB10: 16
A11: 4 Горизонтальная связь | B11: =J18+K18+L18+M18+N18 -> 4 | C11: =AI35 -> 320 | D11: =B11*C11 -> 1280 | E11: =D11*100/$D$16 -> 4.2049934 | F11: =$C$3/100*E11 -> 8.8304862 | G11: =IF(B11=0,0,F11/B11) -> 2.2076216 | N11: Диагонали | O11: В каждую | AA11: 27 | AB11: 18
A12: 5 Мостки (настил) деревянные | B12: =J21*3 -> 12 | C12: =AI36 -> 450 | D12: =B12*C12 -> 5400 | E12: =D12*100/$D$16 -> 17.739816 | F12: =$C$3/100*E12 -> 37.253614 | G12: =IF(B12=0,0,F12/B12) -> 3.1044678 | I12: Итого площадь | L12: =L3+L5+L7+L9 -> 24 | M12: м2 | AA12: 30 | AB12: 20
A13: 6 Ригель для настила | B13: =J21*2 -> 8 | C13: =AI37 -> 1120 | D13: =B13*C13 -> 8960 | E13: =D13*100/$D$16 -> 29.434954 | F13: =$C$3/100*E13 -> 61.813403 | G13: =IF(B13=0,0,F13/B13) -> 7.7266754 | N13: Минималка у транпортной комп | Q13: =O4*2*15+2*520 -> 2540 | R13: =Q13*1.2 -> 3048 | AA13: 33 | AB13: 22 | AG13: 4 | AH13: 7 | AI13: 14 | AJ13: 30 | AK13: 45 | AL13: 60 | AM13: 60
A14: 7 Кронштейн | B14: 0 | C14: 200 | D14: =B14*C14 -> 0 | I14: Количество элементов | AA14: 36 | AB14: 24
A15: 8 Башмак | B15: 0 | C15: 150 | D15: =B15*C15 -> 0 | J15: С1 | K15: С2 | L15: С3 | M15: С4 | N15: Доп связи | AA15: 39 | AB15: 26
A16: Общая рыночная стоимость арендуемого оборудования | D16: =SUM(D8:D15) -> 30440 | I16: всего рам | J16: =(J4+1)*K4 -> 8 | K16: =(J6+1)*K6 -> 0 | L16: =(J8+1)*K8 -> 0 | M16: =(J10+1)*K10 -> 0 | N16: 0 | AA16: 42 | AB16: 28 | AI16: вес | AJ16: объем | AL16: Диагонали
A17: =CONCATENATE("Стоимость залога за оборудование составляет ", O7, "% от общей рыночной стоимости") -> Стоимость залога за оборудование составляет 10% от общей рыночной стоимости | D17: =ROUNDUP(D16/100*O7,-2)+Q23 -> 3100 | I17: с лестницей | J17: =K4*1+K4*Y7 -> 4 | K17: =K6*1+K6*Y7 -> 0 | L17: =K8*1+K8*Y7 -> 0 | M17: =K10*1+K10*Y7 -> 0 | N17: 0 | AA17: 45 | AB17: 30 | AH17: 9.7 | AI17: =10*B8 -> 40 | AJ17: =0.1*B8 -> 0.4 | AL17: В каждую
A18: Стоимость доставки оборудования до объекта Арендатора* | D18: =O2 -> 0 | I18: секций/гор. | J18: =CEILING(J4*K4*AL22,1) -> 4 | K18: =CEILING(J6*K6*AL22,1) -> 0 | L18: =CEILING(J8*K8*AL22,1) -> 0 | M18: =CEILING(J10*K10*AL22,1) -> 0 | N18: 0 | AA18: 48 | AB18: 32 | AH18: 11.7 | AI18: =11.7*B9 -> 46.8 | AJ18: =0.1*B9 -> 0.4 | AL18: В шахматном
A19: Стоимость вывоза оборудования с объекта Арендатора | D19: =O2 -> 0 | I19: диаг связи | J19: =CEILING(J4*K4/AL21,1) -> 4 | K19: =CEILING(J6*K6/AL21,1) -> 0 | L19: =CEILING(J8*K8/AL21,1) -> 0 | M19: =CEILING(J10*K10/AL21,1) -> 0 | N19: 0 | AA19: 51 | AB19: 34 | AH19: 5.6 | AI19: =5.6*B10 -> 22.4 | AJ19: =0.0019*B10 -> 0.0076
A20: Монтаж и демонтаж оборудования | D20: 0 | I20: Настил | J20: кол-во | K20: цена/д | L20: Итого | O20: Надбавка/(дисконт) | S20: желаемая цена | AA20: 54 | AB20: 36 | AH20: 2.6 | AI20: =2.6*B11 -> 10.4 | AJ20: =0.0041*B11 -> 0.0164
A21: Погрузка и выгрузка оборудования | D21: 0 | J21: 4 | K21: =IF(AND(C4<=7),AH9,IF(AND(C4<=14),AI9,IF(AND(C4<=30),AJ9,IF(AND(C4<=45),AK9,IF(AND(C4<=60),AL9, IF(AND(C4>60),AM9, "нету"))))))+Q24 -> 10 | L21: =J21*K21 -> 40 | O21: цена за 1м2 | Q21: 0 | R21: руб. | AA21: 57 | AB21: 38 | AF21: Город | AI21: =15*B12 -> 180 | AJ21: =0.068*B12 -> 0.816 | AL21: =IF(O11="В каждую",1,2) -> 1
A22: =CONCATENATE("Стоимость аренды всего оборудования за ", C4," суток согласно п. 3.1 договора") -> Стоимость аренды всего оборудования за 30 суток согласно п. 3.1 договора | D22: =((C3)*C4)+Q27 -> 6300 | I22: нужно | J22: =M4+M6+M8+M10 -> 4 | O22: аренда в сутки | P22: =S22-C3 -> -210 | Q22: 0 | R22: руб. | S22: 0 | AA22: 60 | AB22: 40 | AF22: Екатеринбург | AG22: 1 | AI22: =9.5*B13 -> 76 | AJ22: =0.0056*B13 -> 0.0448 | AL22: =IF(O11="В каждую",1,1.5) -> 1
I23: 1 настил= | J23: 2 ригеля + 3 щита | O23: Залог | Q23: 0 | R23: руб. | AA23: 63 | AF23: Челябинск | AG23: 1.4
A24: Итого: | D24: =D17+D18+D19+D20+D21+D22+D23 -> 9400 | O24: Настил | Q24: 0 | R24: руб. | AA24: 66 | AF24: Пермь | AG24: 1.15 | AI24: =SUM(AI17:AI22) -> 375.6 | AJ24: =SUM(AJ17:AJ22) -> 1.6848
A25: в т.ч. Залог | D25: =D17 -> 3100 | I25: Процент окупаемости | L25: =IF(C4<=3,3,IF(C4<=7,4,IF(C4<=14,6,IF(C4<=21,8,IF(C4<=30,10,IF(C4<=45,14,IF(C4<=60,17,IF(C4<=90,22,IF(C4<=120,27,IF(C4<=180,32,IF(C4>180,40))))))))))) -> 10 | O25: Рын стоимость | Q25: 0 | AA25: 69 | AF25: Новосибирск | AG25: 1.15 | AJ25: =CEILING(AI24/400,2) -> 2
I26: Рекомендуемая цена | L26: =(D16/100*L25)/C4 -> 101.46667 | M26: руб | AA26: 72
O27: Стоимость всего | Q27: 0 | AA27: 75
AA28: 78
B29: минимум | C29: максимум | AA29: 81
A30: Доставки | AA30: 84 | AH30: коэф повышения | AI30: 1.15
A31: По городу | B31: 900 | AA31: 87 | AI31: наши | AJ31: цены абриса | AK31: стали | AL31: было
A32: Арамиль | B32: 1500 | C32: 1800 | AA32: 90 | AI32: =ROUNDUP(AJ32*$AI$30,-1) -> 1400 | AJ32: 1210 | AK32: 1459 | AL32: 1300 | AM32: 1520
A33: Балтым | B33: 1000 | C33: 1500 | AA33: 93 | AI33: =ROUNDUP(AJ33*$AI$30,-1) -> 1670 | AJ33: 1450 | AK33: 1770 | AL33: 1550 | AM33: 1760
A34: Верхнее Дуброво | B34: 1200 | AA34: 96 | AI34: =ROUNDUP(AJ34*$AI$30,-1) -> 630 | AJ34: 546 | AK34: 730 | AL34: 700 | AM34: 735
A35: Верхняя Пышма | B35: 1300 | C35: 1600 | AA35: 99 | AI35: =ROUNDUP(AJ35*$AI$30,-1) -> 320 | AJ35: 272 | AK35: 356 | AL35: 345 | AM35: 367
A36: Гагарский пос. | B36: 1500 | AA36: 102 | AI36: =ROUNDUP(AJ36*$AI$30,-1) -> 450 | AJ36: 390 | AK36: 390 | AL36: 390 | AM36: 390
A37: Горный Щит | B37: 1500 | AA37: 105 | AI37: =ROUNDUP(AJ37*$AI$30,-1) -> 1120 | AJ37: 970 | AK37: 1440 | AL37: 1150 | AM37: 1390
A38: Сухой лог, Глядены | B38: 3500 | AA38: 108
A39: Исток | B39: 1200 | C39: 1500 | AA39: 111
A40: Клевер | B40: 1800 | AA40: 114
...

Sheet Вышки туры
A1: УПСК Аренда вышек тур | B1: Параметры цен | F1: Высота (полная) | G1: 3.89 | H1: =G1+1 -> 4.89 | I1: город | J1: Екатеринбург | L1: к= | M1: =IF(J1="Екатеринбург",Z14,IF(J1="Челябинск",Z15,IF(J1="Новосибирск",Z16,IF(J1="Пермь",Z17)))) -> 1 | S1: Кол-во метров/ срок аренды | T1: До 4-х дней | U1: До недели | V1: До 2-х недель | W1: До 3х недель | X1: До 30дн | Y1: До 45 дней | Z1: Св 45 дней
F2: Кол-во дней | G2: 30 | Q2: 3.89 | R2: Вышка-тура | S2: до 3,89м | T2: 290 | U2: 230 | V2: 170 | W2: 150 | X2: 130 | Y2: 110 | Z2: 95
B3: ст-ть аренды | C3: =IF(AND(G2<=T8,G1<=Q2),T2, IF(AND(G2<=U8,G1<=Q2),U2, IF(AND(G2<=V8,G1<=Q2),V2, IF(AND(G2<=W8,G1<=Q2),W2, IF(AND(G2<=X8,G1<=Q2),X2, IF(AND(G2<=Y8,G1<=Q2),Y2, IF(AND(G2>Z8,G1<=Q2),Z2, IF(AND(G2<=T8,G1<=Q3),T3, IF(AND(G2<=U8,G1<=Q3),U3, IF(AND(G2<=V8,G1<=Q3),V3, IF(AND(G2<=W8,G1<=Q3),W3, IF(AND(G2<=X8,G1<=Q3),X3, IF(AND(G2<=Y8,G1<=Q3),Y3, IF(AND(G2>Z8,G1<=Q3),Z3, IF(AND(G2<=T8,G1<=Q4),T4, IF(AND(G2<=U8,G1<=Q4),U4, IF(AND(G2<=V8,G1<=Q4),V4, IF(AND(G2<=W8,G1<=Q4),W4, IF(AND(G2<=X8,G1<=Q4),X4, IF(AND(G2<=Y8,G1<=Q4),Y4, IF(AND(G2>Z8,G1<=Q4),Z4, IF(AND(G2<=T8,G1<=Q5),T5, IF(AND(G2<=U8,G1<=Q5),U5, IF(AND(G2<=V8,G1<=Q5),V5, IF(AND(G2<=W8,G1<=Q5),W5, IF(AND(G2<=X8,G1<=Q5),X5, IF(AND(G2<=Y8,G1<=Q5),Y5, IF(AND(G2>Z8,G1<=Q5),Z5, IF(AND(G2<=T8,G1<=Q6),T6, IF(AND(G2<=U8,G1<=Q6),U6, IF(AND(G2<=V8,G1<=Q6),V6, IF(AND(G2<=W8,G1<=Q6),W6, IF(AND(G2<=X8,G1<=Q6),X6, IF(AND(G2<=Y8,G1<=Q6),Y6, IF(AND(G2>Z8,G1<=Q6),Z6, IF(AND(G2<=T8,G1<=Q7),T7, IF(AND(G2<=U8,G1<=Q7),U7, IF(AND(G2<=V8,G1<=Q7),V7, IF(AND(G2<=W8,G1<=Q7),W7, IF(AND(G2<=X8,G1<=Q7),X7, IF(AND(G2<=Y8,G1<=Q7),Y7, IF(AND(G2>Z8,G1<=Q7),Z7,1300 ))))))))))))))))))))))))))))))))))))))))))*M1*L6+C6+K7 -> 156 | D3: в сутки | F3: Кол-во вышек | G3: 1 | H3: =T14 -> 20900 | I3: 0 | K3: =G5*G3 -> 2090 | Q3: 6.29 | R3: Вышка-тура | S3: до 6,29м | T3: 400 | U3: 320 | V3: 230 | W3: 210 | X3: 180 | Y3: 150 | Z3: 130
B4: ст-ть аренды за весь период | D4: =G2*C3 -> 4680 | F4: Доставка | G4: 0 | I4: 10 | J4: % | Q4: 8.69 | R4: Вышка-тура | S4: до 8,69м | T4: 480 | U4: 380 | V4: 270 | W4: 250 | X4: 220 | Y4: 180 | Z4: 160
B5: =C3*G3 -> 156 | C5: =CONCATENATE("за ",G3," шт.") -> за 1 шт. | D5: =D4*G3 -> 4680 | F5: =CONCATENATE("Залог ",I4,"%") -> Залог 10% | G5: =ROUNDUP((H3/100*I4+I3),0) -> 2090 | K5: Скидка | L5: =IF(J7="ПСРВ-21",0.85,1.05) -> 0.85 | Q5: 11.09 | R5: Вышка-тура | S5: до 11,09 | T5: 550 | U5: 440 | V5: 320 | W5: 290 | X5: 260 | Y5: 210 | Z5: 180
B6: корректировка аренды в день + | F6: Итого | G6: =(G2*C3+G5)*G3+G4*2 -> 6770 | K6: ндс | L6: 1.2 | Q6: 13.49 | R6: Вышка-тура | S6: до 13,49 | T6: 630 | U6: 500 | V6: 360 | W6: 330 | X6: 295 | Y6: 240 | Z6: 210
C7: =C6/(C3+C6) -> 0 | F7: Аренда | G7: =D5 -> 4680 | I7: Вышка | J7: ПСРВ-21 | K7: =IF(J7="ПСРВ-22",50,0) -> 0 | Q7: 14.69 | R7: Вышка-тура | S7: от 14,69 | T7: 720 | U7: 560 | V7: 410 | W7: 370 | X7: 330 | Y7: 270 | Z7: 240
A8: окупаемость 4 месяца = | B8: =H3/120 -> 174.16667 | C8: % окупаемости | D8: =IF(G2<=3,3,IF(G2<=7,4,IF(G2<=14,6,IF(G2<=21,8,IF(G2<=30,10,IF(G2<=45,14,IF(G2<=60,17,IF(G2<=90,22,IF(G2<=120,27,IF(G2<=180,32,IF(G2>180,40))))))))))) -> 10 | F8: Залог | G8: =G5*G3 -> 2090 | I8: Площадка | J8: =IF(J7="ПСРВ-21","2м на 1,2м","2м на 2м.") -> 2м на 1,2м | T8: 4 | U8: 7 | V8: 14 | W8: 21 | X8: 30 | Y8: 45 | Z8: 45
C9: Рек цена | D9: =ROUND(((H3/100*D8)/G2)*1.2,0) -> 84 | F9: Доставка | G9: =G4*2 -> 0 | L9: 0.1
A11: Рабочая площадка 2000 х1200 мм
A12: ПСРВ – 21 | B12: Высота полная, м | C12: Высота до настила, м | D12: Достигаемая высота, м | E12: Масса, кг | F12: Цена, руб. | H12: абрис | I12: секций | S12: =G1 -> 3.89
B13: 2.69 | C13: 1.69 | D13: 3.69 | E13: 126.7 | F13: =H13+H13*L9 -> 17050 | G13: =F13+$I$3 -> 17050 | H13: =IF($J$7="ПСРВ-21",X20,Y20) -> 15500 | I13: 1 | V13: Вышка | Y13: Город
B14: 3.89 | C14: 2.89 | D14: 4.89 | E14: 151.5 | F14: =H14+H14*L9 -> 20900 | G14: =F14+$I$3 -> 20900 | H14: =IF($J$7="ПСРВ-21",X21,Y21) -> 19000 | I14: 2 | S14: Расчет залога | T14: =IF(G1=B13,F13,IF(G1=B14,F14,IF(G1=B15,F15,IF(G1=B16,F16,IF(G1=B17,F17,IF(G1=B18,F18,IF(G1=B19,F19,IF(G1=B20,F20,IF(G1=B21,F21,IF(G1=B22,F22,IF(G1=B23,F23,IF(G1=B24,F24,IF(G1=B25,F25,IF(G1=B26,F26,IF(G1=B27,F27,IF(G1=B28,F28,)))))))))))))))) -> 20900 | V14: Столбец1 | Y14: Екатеринбург | Z14: 1
B15: 5.09 | C15: 4.09 | D15: 6.09 | E15: 192.3 | F15: =H15+H15*L9 -> 24200 | G15: =F15+$I$3 -> 24200 | H15: =IF($J$7="ПСРВ-21",X22,Y22) -> 22000 | I15: 3 | V15: ПСРВ-21 | Y15: Челябинск | Z15: 1.15
B16: 6.29 | C16: 5.29 | D16: 7.29 | E16: 218.8 | F16: =H16+H16*L9 -> 28820 | G16: =F16+$I$3 -> 28820 | H16: =IF($J$7="ПСРВ-21",X23,Y23) -> 26200 | I16: 4 | S16: =C3*G3 -> 156 | V16: ПСРВ-22 | Y16: Новосибирск | Z16: 1.4
B17: 7.49 | C17: 6.49 | D17: 8.49 | E17: 243.8 | F17: =H17+H17*L9+5 -> 32125 | G17: =F17+$I$3 -> 32125 | H17: =IF($J$7="ПСРВ-21",X24,Y24) -> 29200 | I17: 5 | Y17: Пермь | Z17: 1.15
B18: 8.69 | C18: 7.69 | D18: 9.69 | E18: 270.3 | F18: =H18+H18*0.1+5 -> 35315 | G18: =F18+$I$3 -> 35315 | H18: =IF($J$7="ПСРВ-21",X25,Y25) -> 32100 | I18: 6
B19: 9.89 | C19: 8.89 | D19: 10.89 | E19: 295.1 | F19: =H19+H19*L9+5 -> 38725 | G19: =F19+$I$3 -> 38725 | H19: =IF($J$7="ПСРВ-21",X26,Y26) -> 35200 | I19: 7
B20: 11.09 | C20: 10.09 | D20: 12.09 | E20: 319.9 | F20: =H20+H20*L9+5 -> 41915 | G20: =F20+$I$3 -> 41915 | H20: =IF($J$7="ПСРВ-21",X27,Y27) -> 38100 | I20: 8 | X20: 15500 | Y20: 21400 | AC20: База в сборе (2420мм) | AD20: База в сборе (2420мм)
B21: 12.29 | C21: 11.29 | D21: 13.29 | E21: 344.7 | F21: =H21+H21*L9+5 -> 45215 | G21: =F21+$I$3 -> 45215 | H21: =IF($J$7="ПСРВ-21",X28,Y28) -> 41100 | I21: 9 | X21: 19000 | Y21: 25140 | AC21: Лестница секции (1160мм х 1214мм) | AD21: Лестница секции (1160мм х 1930мм)
B22: 13.49 | C22: 12.49 | D22: 14.49 | E22: 369.5 | F22: =H22+H22*L9 -> 48510 | G22: =F22+$I$3 -> 48510 | H22: =IF($J$7="ПСРВ-21",X29,Y29) -> 44100 | I22: 10 | X22: 22000 | Y22: 28900 | AC22: Диагональ объемная (2305мм) | AD22: Диагональ объемная (2776мм)
B23: 14.69 | C23: 13.69 | D23: 15.69 | E23: 394.3 | F23: =H23+H23*L9 -> 51700 | G23: =F23+$I$3 -> 51700 | H23: =IF($J$7="ПСРВ-21",X30,Y30) -> 47000 | I23: 11 | X23: 26200 | Y23: 34900 | AC23: Гантель (1975мм) | AD23: Гантель (1975мм)
B24: 15.89 | C24: 14.89 | D24: 16.89 | E24: 419.1 | F24: =H24+H24*L9 -> 55110 | G24: =F24+$I$3 -> 55110 | H24: =IF($J$7="ПСРВ-21",X31,Y31) -> 50100 | I24: 12 | X24: 29200 | Y24: 38500 | AC24: Стяжка лестницы (840мм) | AD24: Стяжка лестницы (840мм)
B25: 17.09 | C25: 16.09 | D25: 18.09 | E25: 443.9 | F25: =H25+H25*L9 -> 58300 | G25: =F25+$I$3 -> 58300 | H25: =IF($J$7="ПСРВ-21",X32,Y32) -> 53000 | I25: 13 | X25: 32100 | Y25: 42500 | AC25: Стабилизатор в сборе (2400мм) | AD25: Стабилизатор в сборе (2400мм)
B26: 18.29 | C26: 17.29 | D26: 19.29 | E26: 468.7 | F26: =H26+H26*L9 -> 61600 | G26: =F26+$I$3 -> 61600 | H26: =IF($J$7="ПСРВ-21",X33,Y33) -> 56000 | I26: 14 | X26: 35200 | Y26: 46300 | AC26: Лестница ограждения (1160мм х 1214мм) | AD26: Лестница ограждения (1160мм х 1930мм)
B27: 19.49 | C27: 18.49 | D27: 20.49 | E27: 493.5 | F27: =H27+H27*L9 -> 64790 | G27: =F27+$I$3 -> 64790 | H27: =IF($J$7="ПСРВ-21",X34,Y34) -> 58900 | I27: 15 | X27: 38100 | Y27: 50000 | AC27: Гантель ограждения (1965мм) | AD27: Гантель ограждения (1965мм)
B28: 20.69 | C28: 19.69 | D28: 21.69 | E28: 518.3 | F28: =H28+H28*L9+5 -> 68205 | G28: =F28+$I$3 -> 68205 | H28: =IF($J$7="ПСРВ-21",X35,Y35) -> 62000 | I28: 16 | X28: 41100 | Y28: 53700 | AC28: Перекладина ограждения (1990мм) | AD28: Перекладина ограждения (1990мм)
H29: =IF($J$7="ПСРВ-21",X36,Y36) -> 0 | X29: 44100 | Y29: 57700 | AC29: Настил без люка (1995мм х 525мм) | AD29: Настил без люка (1995мм х 525мм)
X30: 47000 | Y30: 61000 | AC30: Настил с люком (1995мм х 525мм) | AD30: Настил с люком (1995мм х 525мм)
X31: 50100 | Y31: 65100
X32: 53000 | Y32: 69200
A33: Комплектующие | D33: =CONCATENATE("Количество на ",G3," вышки") -> Количество на 1 вышки | G33: Цена за элемент | J33: коэф | X33: 56000 | Y33: 72800
H34: 1.1 | J34: =IF(G1=2.69,1,IF(G1=3.89,2,IF(G1=5.09,3,IF(G1=6.29,4,IF(G1=7.49,5,IF(G1=8.69,6,IF(G1=9.89,7,IF(G1=11.09,8,IF(G1=12.29,9,IF(G1=13.49,10,IF(G1=14.69,11,IF(G1=15.89,12,IF(G1=17.09,13,IF(G1=18.29,14,IF(G1=19.49,15,IF(G1=20.69,16)))))))))))))))) -> 2 | X34: 58900 | Y34: 76500
G35: абрис | H35: с ндс наши | I35: итого | X35: 62000 | Y35: 80600
A36: =IF($J$7="ПСРВ-21",AC20,AD20) -> База в сборе (2420мм) | B36: 2 | D36: =B36*G3 -> 2 | G36: 3774 | H36: =ROUNDUP(G36*$H$34,-1) -> 4160 | I36: =D36*H36 -> 8320 | Y36: 83900
A37: =IF($J$7="ПСРВ-21",AC21,AD21) -> Лестница секции (1160мм х 1214мм) | B37: =2*J34+B42 -> 6 | D37: =B37*G3 -> 6 | G37: 1180 | H37: =ROUNDUP(G37*$H$34,-1) -> 1300 | I37: =D37*H37 -> 7800
A38: =IF($J$7="ПСРВ-21",AC22,AD22) -> Диагональ объемная (2305мм) | B38: =ROUNDUP(J34/3,0) -> 1 | D38: =B38*G3 -> 1 | G38: 571 | H38: =ROUNDUP(G38*$H$34,-1) -> 630 | I38: =D38*H38 -> 630
A39: =IF($J$7="ПСРВ-21",AC23,AD23) -> Гантель (1975мм) | B39: =2*J34 -> 4 | D39: =B39*G3 -> 4 | G39: 781 | H39: =ROUNDUP(G39*$H$34,-1) -> 860 | I39: =D39*H39 -> 3440
A40: =IF($J$7="ПСРВ-21",AC24,AD24) -> Стяжка лестницы (840мм) | B40: =8+8*J34 -> 24 | D40: =B40*G3 -> 24 | G40: 122 | H40: =ROUNDUP(G40*$H$34,-1) -> 140 | I40: =D40*H40 -> 3360
A41: =IF($J$7="ПСРВ-21",AC25,AD25) -> Стабилизатор в сборе (2400мм) | B41: =IF(G1>=6.29,4,0) -> 0 | D41: =B41*G3 -> 0 | G41: 779 | H41: =ROUNDUP(G41*$H$34,-1) -> 860 | I41: =D41*H41 -> 0
...

Sheet Договор аренды лесов Физ
A1: ='Расчет лесов'!C3 -> 210
A2: =CONCATENATE("ДОГОВОР №",AW2) -> ДОГОВОР №27/06-А(16) | AV2: № договора | AW2: 27/06-А(16) | BK2: Вспомогательные значения
A3: на аренду строительных лесов | AV3: Дата | AW3: "27" июня 2016 г. | BK3: Срок аренды | BL3: ='Расчет лесов'!C4 -> 30
AV4: ФИО | AW4: __________________________________
B5: г. Екатеринбург | AK5: =AW3 -> "27" июня 2016 г. | AV5: Город | AW5: ______________________________________ | BK5: длина | BL5: ='Расчет лесов'!J3+'Расчет лесов'!J5+'Расчет лесов'!J7+'Расчет лесов'!J9 -> 3
AV6: Улица | BK6: высота | BL6: ='Расчет лесов'!K3+'Расчет лесов'!K5+'Расчет лесов'!K7+'Расчет лесов'!K9 -> 8
C7: Гражданин Выборных Андрей Павлович, проживающий по адресу: г. Екатеринбург, ул. | AV7: Паспорт | AW7: _____________
A8: Боровая, д. 24, кв. 163, паспорт серия 6505 N 554016 выдан "29" июля 2005г. ОВД г Краснотурьинска Свердловской области, именуемый в дальнейшем "Арендодатель", с одной стороны, и | AV8: выдан когда | AW8: ______________
AV9: выдан кем | AW9: _________________________________________________
C11: Гражданин(ка) | J11: _______________________________________________________________ | AV11: сумма в сутки | AW11: =SUBSTITUTE(PROPER(INDEX(n_4,MID(TEXT(A1,n0),1,1)+1)&INDEX(n0x,MID(TEXT(A1,n0),2,1)+1,MID(TEXT(A1,n0),3,1)+1)&IF(-MID(TEXT(A1,n0),1,3),"миллиард"&VLOOKUP(MID(TEXT(A1,n0),3,1)*AND(MID(TEXT(A1,n0),2,1)-1),мил,2),"")&INDEX(n_4,MID(TEXT(A1,n0),4,1)+1)&INDEX(n0x,MID(TEXT(A1,n0),5,1)+1,MID(TEXT(A1,n0),6,1)+1)&IF(-MID(TEXT(A1,n0),4,3),"миллион"&VLOOKUP(MID(TEXT(A1,n0),6,1)*AND(MID(TEXT(A1,n0),5,1)-1),мил,2),"")&INDEX(n_4,MID(TEXT(A1,n0),7,1)+1)&INDEX(n1x,MID(TEXT(A1,n0),8,1)+1,MID(TEXT(A1,n0),9,1)+1)&IF(-MID(TEXT(A1,n0),7,3),VLOOKUP(MID(TEXT(A1,n0),9,1)*AND(MID(TEXT(A1,n0),8,1)-1),тыс,2),"")&INDEX(n_4,MID(TEXT(A1,n0),10,1)+1)&INDEX(n0x,MID(TEXT(A1,n0),11,1)+1,MID(TEXT(A1,n0),12,1)+1)),"z"," ")&IF(TRUNC(TEXT(A1,n0)),"","Ноль ")&"рубл"&VLOOKUP(MOD(MAX(MOD(MID(TEXT(A1,n0),11,2)-11,100),9),10),{0,"ь ";1,"я ";4,"ей "},2)&RIGHT(TEXT(A1,n0),2)&" копе"&VLOOKUP(MOD(MAX(MOD(RIGHT(TEXT(A1,n0),2)-11,100),9),10),{0,"йка";1,"йки";4,"ек"},2) -> Двести десять рублей 00 копеек
A12: проживающий по адресу:_________________________________________________________ | AV12: конт телефон
A13: паспорт серия/номер__________________ | V13: выдан _____________________________________ | AV13: Адрес доставки
A14: именуемый в дальнейшем "Арендатор", с другой стороны, заключили настоящий Договор
A15: о нижеследующем:
A17: 1. ПРЕДМЕТ ДОГОВОРА
A19: =CONCATENATE("1.1. Арендодатель обязуется предоставить во временное владение и пользование Арендатору строительные леса (длина ",BL5,"м, высота ",BL6,"м) согласно Акту приема-передачи (приложение №1) настоящего договора, именуемые в дальнейшем «оборудование».") -> 1.1. Арендодатель обязуется предоставить во временное владение и пользование Арендатору строительные леса (длина 3м, высота 8м) согласно Акту приема-передачи (приложение №1) настоящего договора, именуемые в дальнейшем «оборудование».
A22: 1.2. Оборудование будет использоваться по прямому назначению.
A23: 1.3. Оборудование передается в состоянии, пригодном для его использования в соответствии с пунктом 1.2. настоящего договора.
A25: 2. ОБЯЗАННОСТИ СТОРОН
A27: 2.1. Арендодатель обязан: 2.1.1. Передать Арендатору арендованное имущество в состоянии, отвечающем условиям Договора, в течение трех рабочих дней с момента подписания договора и получения аванса. 2.1.2. Оказывать консультативную и иную помощь в целях наиболее эффективного использования арендованного имущества. 2.1.3. Обязан осуществить все иные действия, необходимые для исполнения данного договора, предусмотренные законодательством, настоящим договором и дополнениями к нему. 2.2. Арендатор обязан: 2.2.1. Использовать имущество в соответствии с условиями Договора и назначением имущества. 2.2.2. Поддерживать имущество в исправном состоянии, производить за свой счет текущий ремонт. 2.2.3. Нести иные расходы по содержанию имущества. 2.2.4. В установленные Договором сроки вносить арендную плату. 2.2.5. Возвратить имущество Арендодателю после прекращения Договора по Акту приема-передачи в том состоянии, в каком оно было передано, с учетом нормального износа. 2.2.6. Производить ежедневную проверку исправности имущества. 2.2.7. Провести инструктаж по технике безопасности при работе с имуществом. 2.2.8. Письменно уведомить Арендодателя при смене местонахождения оборудования. 2.2.9. Исполнитель обязан осуществить все иные действия, необходимые для исполнения данного договора, предусмотренные законодательством, настоящим договором и дополнениями к нему.
A47: 3. РАСЧЕТЫ
A49: 3.1. Арендная плата по настоящему договору составляет:
C50: =CONCATENATE('Расчет лесов'!C3," (",AW11,") за каждые сутки аренды.") -> 210 (Двести десять рублей 00 копеек) за каждые сутки аренды.
A51: 3.2. Оплата производится по безналичному расчету, либо другими способами удовлетворяющими обе стороны путем выдачи Арендодателю раз в две недели суммы (за 14 дней), определенной пунктом 3.1. договора. 3.3 Залог Арендатору возвращается в полном объеме после возврата оборудования Арендодателю в исправном состоянии.
A57: 4. ОТВЕТСТВЕННОСТЬ СТОРОН
A59: 4.1. Стороны несут имущественную ответственность за неисполнение или ненадлежащее исполнение условий Договора. 4.2. За каждый день просрочки выплаты арендной платы начисляется пеня в размере 5% от суммы задолженности. 4.3. В случае просрочки внесения арендной платы свыше одного месяца Арендодатель имеет право расторгнуть Договор и потребовать возмещения убытков, причиненных этой просрочкой. 4.4. За просрочку предоставления арендуемого имущества в установленный договором срок Арендодатель уплачивает Арендатору пени в размере 50 % за каждый день просрочки от суммы арендной платы за день. 4.5. За просрочку возврата арендованного имущества в установленный договором срок Арендатор уплачивает Арендодателю пени в размере 50% за каждый день просрочки от суммы арендной платы за день. 4.6. При возврате неисправного арендованного имущества, поврежденного по вине Арендатора, что подтверждается двусторонним актом, последний уплачивает Арендодателю расходы по ремонту их и штраф в размере 100% стоимости поврежденного арендованного имущества. 4.7. Уплата неустойки не освобождает стороны от исполнения обязательств или устранения нарушений. 4.8. Арендодатель не несет ответственность за несчастные случаи допущенные вследствие нарушении техники безопасности.
A79: 5. ФОРС-МАЖОР
A81: 5.1. Ни одна из сторон не несет ответственности перед другой стороной за невыполнение обязательств, обусловленное обстоятельствами, возникшими помимо воли и желания сторон и которые нельзя предвидеть или избежать, включая объявленную или фактическую войну, гражданские волнения, эпидемии, блокаду, эмбарго, землетрясения, наводнения, пожары и другие стихийные бедствия. 5.2. Сторона, которая не может исполнить своего обязательства, должна известить другую сторону о препятствии и его влиянии на исполнение обязательств по Договору в разумный срок с момента возникновения этих обстоятельств. 5.3. Дальнейшая судьба настоящего договора в таких случаях должна быть определена соглашением сторон. При не достижении согласия стороны вправе обратиться в суд для решения этого вопроса.
A93: 6. ПОРЯДОК РАЗРЕШЕНИЯ СПОРОВ
A95: 6.1. Все споры или разногласия, возникающие между сторонами по настоящему Договору или в связи с ним, разрешаются путем переговоров между сторонами. 6.2. В случае невозможности разрешения разногласий путем переговоров они подлежат рассмотрению в суде общей юрисдикции в установленном законодательством порядке.
A100: 7. КОНФИДЕНЦИАЛЬНОСТЬ
A102: 7.1. Условия настоящего договора и соглашений (протоколов и т.п.) к нему конфиденциальны и не подлежат разглашению. 7.2. Стороны принимают все необходимые меры для того, чтобы их сотрудники, агенты, правопреемники без предварительного согласия другой стороны не информировали третьих лиц о деталях данного договора и приложений к нему.
A108: 8. ПОРЯДОК ИЗМЕНЕНИЯ И ДОПОЛНЕНИЯ ДОГОВОРА
A110: 8.1. Любые изменения и дополнения к настоящему Договору имеют силу только в том случае, если они оформлены в письменном виде и подписаны обеими сторонами. 8.2. Досрочное расторжение Договора может иметь место по соглашению сторон либо по основаниям, предусмотренным действующим на территории Российской Федерации гражданским законодательством, с возмещением понесенных убытков.
A116: 9. ЗАКЛЮЧИТЕЛЬНЫЕ ПОЛОЖЕНИЯ
... A124: 10. ЮРИДИЧЕСКИЕ АДРЕСА И ПЛАТЕЖНЫЕ РЕКВИЗИТЫ СТОРОН
B126: Арендодатель:
B127: Выборных Андрей Павлович, паспорт серия 6505 N 554016 выдан "29" июля 2005г. ОВД г Краснотурьинска Свердловской области, конт. тел. 8(343)206-88-82
B129: №карты Сбербанка 5469 1600 1322 4162
B130: Арендатор:
...

Sheet Договор аренды тур Физ
A1: ='Вышки туры'!B5 -> 156
A2: =CONCATENATE("ДОГОВОР №",AW2) -> ДОГОВОР №14/06-А(16) | AV2: № договора | AW2: 14/06-А(16) | BK2: Вспомогательные значения
A3: на аренду вышки туры | AV3: Дата | AW3: "14" июня 2016 г. | BK3: Срок аренды | BL3: ='Вышки туры'!G2 -> 30
AV4: ФИО | AW4: ____________________________
B5: г. Екатеринбург | AK5: =AW3 -> "14" июня 2016 г. | AV5: Город | AW5: ______________________
AV6: Улица | AW6: ____________________________
C7: Гражданин Выборных Андрей Павлович, проживающий по адресу: г. Екатеринбург, ул. | AV7: Паспорт | AW7: ______________
A8: Боровая, д. 24, кв. 163, паспорт серия 6505 N 554016 выдан "29" июля 2005г. ОВД г Краснотурьинска Свердловской области, именуемый в дальнейшем "Арендодатель", с одной стороны, и | AV8: выдан когда | AW8: ______________________________
AV9: выдан кем | AW9: _________________________________________________________
C11: Гражданин(ка) | J11: _______________________________________________________________ | AV11: сумма в сутки | AW11: =SUBSTITUTE(PROPER(INDEX(n_4,MID(TEXT(A1,n0),1,1)+1)&INDEX(n0x,MID(TEXT(A1,n0),2,1)+1,MID(TEXT(A1,n0),3,1)+1)&IF(-MID(TEXT(A1,n0),1,3),"миллиард"&VLOOKUP(MID(TEXT(A1,n0),3,1)*AND(MID(TEXT(A1,n0),2,1)-1),мил,2),"")&INDEX(n_4,MID(TEXT(A1,n0),4,1)+1)&INDEX(n0x,MID(TEXT(A1,n0),5,1)+1,MID(TEXT(A1,n0),6,1)+1)&IF(-MID(TEXT(A1,n0),4,3),"миллион"&VLOOKUP(MID(TEXT(A1,n0),6,1)*AND(MID(TEXT(A1,n0),5,1)-1),мил,2),"")&INDEX(n_4,MID(TEXT(A1,n0),7,1)+1)&INDEX(n1x,MID(TEXT(A1,n0),8,1)+1,MID(TEXT(A1,n0),9,1)+1)&IF(-MID(TEXT(A1,n0),7,3),VLOOKUP(MID(TEXT(A1,n0),9,1)*AND(MID(TEXT(A1,n0),8,1)-1),тыс,2),"")&INDEX(n_4,MID(TEXT(A1,n0),10,1)+1)&INDEX(n0x,MID(TEXT(A1,n0),11,1)+1,MID(TEXT(A1,n0),12,1)+1)),"z"," ")&IF(TRUNC(TEXT(A1,n0)),"","Ноль ")&"рубл"&VLOOKUP(MOD(MAX(MOD(MID(TEXT(A1,n0),11,2)-11,100),9),10),{0,"ь ";1,"я ";4,"ей "},2)&RIGHT(TEXT(A1,n0),2)&" копе"&VLOOKUP(MOD(MAX(MOD(RIGHT(TEXT(A1,n0),2)-11,100),9),10),{0,"йка";1,"йки";4,"ек"},2) -> Сто пятьдесят шесть рублей 00 копеек
A12: проживающий по адресу:_________________________________________________________ | AV12: конт телефон | AW12: ___________________________
A13: паспорт серия/номер__________________ | V13: выдан _____________________________________ | AV13: Адрес доставки | AW13: ___________________
A14: именуемый в дальнейшем "Арендатор", с другой стороны, заключили настоящий Договор
A15: о нижеследующем:
A17: 1. ПРЕДМЕТ ДОГОВОРА
A19: 1.1. Арендодатель обязуется предоставить во временное владение и пользование Арендатору строительные леса согласно Акту приема-передачи (приложение №1") настоящего договора), именуемые в дальнейшем «оборудование».
A22: 1.2. Оборудование будет использоваться по прямому назначению.
A23: 1.3. Оборудование передается в состоянии, пригодном для его использования в соответствии с пунктом 1.2. настоящего договора.
A25: 2. ОБЯЗАННОСТИ СТОРОН
A27: 2.1. Арендодатель обязан: 2.1.1. Передать Арендатору арендованное имущество(вышка тура ПСРВ-21 высотой 8,69м - 1 штука) в состоянии, отвечающем условиям Договора, в течение двух календарных дней с момента подписания договора и получения аванса. 2.1.2. Оказывать консультативную и иную помощь в целях наиболее эффективного использования арендованного имущества. 2.1.3. Обязан осуществить все иные действия, необходимые для исполнения данного договора, предусмотренные законодательством, настоящим договором и дополнениями к нему. 2.2. Арендатор обязан: 2.2.1. Использовать имущество в соответствии с условиями Договора и назначением имущества. 2.2.2. Поддерживать имущество в исправном состоянии, производить за свой счет текущий ремонт. 2.2.3. Нести иные расходы по содержанию имущества. 2.2.4. В установленные Договором сроки вносить арендную плату. 2.2.5. Возвратить имущество Арендодателю после прекращения Договора по Акту приема-передачи в том состоянии, в каком оно было передано, с учетом нормального износа. 2.2.6. Производить ежедневную проверку исправности имущества. 2.2.7. Провести инструктаж по технике безопасности при работе с имуществом. 2.2.8. Письменно уведомить Арендодателя при смене местонахождения оборудования. 2.2.9. Исполнитель обязан осуществить все иные действия, необходимые для исполнения данного договора, предусмотренные законодательством, настоящим договором и дополнениями к нему.
A47: 3. РАСЧЕТЫ
A49: 3.1. Арендная плата по настоящему договору составляет:
C50: =CONCATENATE('Вышки туры'!B5," (",AW11,") за каждые сутки аренды.") -> 156 (Сто пятьдесят шесть рублей 00 копеек) за каждые сутки аренды.
A51: 3.2. Оплата производится по безналичному расчету, либо другими способами удовлетворяющими обе стороны путем выдачи Арендодателю раз в две недели суммы (за 14 дней), определенной пунктом 3.1. договора на основании расписки между сторонами. 3.3 Залог Арендатору возвращается в полном объеме после возврата оборудования Арендодателю в исправном состоянии.
A57: 4. ОТВЕТСТВЕННОСТЬ СТОРОН
A59: 4.1. Стороны несут имущественную ответственность за неисполнение или ненадлежащее исполнение условий Договора. 4.2. За каждый день просрочки выплаты арендной платы начисляется пеня в размере 5% от суммы задолженности. 4.3. В случае просрочки внесения арендной платы свыше одного месяца Арендодатель имеет право расторгнуть Договор и потребовать возмещения убытков, причиненных этой просрочкой. 4.4. За просрочку предоставления арендуемого имущества в установленный договором срок Арендодатель уплачивает Арендатору пени в размере 50 % за каждый день просрочки от суммы арендной платы за день. 4.5. За просрочку возврата арендованного имущества в установленный договором срок Арендатор уплачивает Арендодателю пени в размере 50% за каждый день просрочки от суммы арендной платы за день. 4.6. При возврате неисправного арендованного имущества, поврежденного по вине Арендатора, что подтверждается двусторонним актом, последний уплачивает Арендодателю расходы по ремонту их и штраф в размере 100% стоимости поврежденного арендованного имущества. 4.7. Уплата неустойки не освобождает стороны от исполнения обязательств или устранения нарушений. 4.8. Арендодатель не несет ответственность за несчастные случаи допущенные вследствие нарушении техники безопасности.
A79: 5. ФОРС-МАЖОР
A81: 5.1. Ни одна из сторон не несет ответственности перед другой стороной за невыполнение обязательств, обусловленное обстоятельствами, возникшими помимо воли и желания сторон и которые нельзя предвидеть или избежать, включая объявленную или фактическую войну, гражданские волнения, эпидемии, блокаду, эмбарго, землетрясения, наводнения, пожары и другие стихийные бедствия. 5.2. Сторона, которая не может исполнить своего обязательства, должна известить другую сторону о препятствии и его влиянии на исполнение обязательств по Договору в разумный срок с момента возникновения этих обстоятельств. 5.3. Дальнейшая судьба настоящего договора в таких случаях должна быть определена соглашением сторон. При не достижении согласия стороны вправе обратиться в суд для решения этого вопроса.
A93: 6. ПОРЯДОК РАЗРЕШЕНИЯ СПОРОВ
A95: 6.1. Все споры или разногласия, возникающие между сторонами по настоящему Договору или в связи с ним, разрешаются путем переговоров между сторонами. 6.2. В случае невозможности разрешения разногласий путем переговоров они подлежат рассмотрению в суде общей юрисдикции в установленном законодательством порядке.
A100: 7. КОНФИДЕНЦИАЛЬНОСТЬ
A102: 7.1. Условия настоящего договора и соглашений (протоколов и т.п.) к нему конфиденциальны и не подлежат разглашению. 7.2. Стороны принимают все необходимые меры для того, чтобы их сотрудники, агенты, правопреемники без предварительного согласия другой стороны не информировали третьих лиц о деталях данного договора и приложений к нему.
A108: 8. ПОРЯДОК ИЗМЕНЕНИЯ И ДОПОЛНЕНИЯ ДОГОВОРА
A110: 8.1. Любые изменения и дополнения к настоящему Договору имеют силу только в том случае, если они оформлены в письменном виде и подписаны обеими сторонами. 8.2. Досрочное расторжение Договора может иметь место по соглашению сторон либо по основаниям, предусмотренным действующим на территории Российской Федерации гражданским законодательством, с возмещением понесенных убытков.
A116: 9. ЗАКЛЮЧИТЕЛЬНЫЕ ПОЛОЖЕНИЯ
... A124: 10. ЮРИДИЧЕСКИЕ АДРЕСА И ПЛАТЕЖНЫЕ РЕКВИЗИТЫ СТОРОН
B126: Арендодатель:
B127: Выборных Андрей Павлович, паспорт серия 6505 N 554016 выдан "29" июля 2005г. ОВД г Краснотурьинска Свердловской области, конт. тел. 8(343)206-88-82
B129: №карты Сбербанка 5469 1600 1322 4162
B130: Арендатор:
...

Sheet ДляДоговора
A1: Реквизиты контрагента | D1: Дата для договора
A2: № договора | B2: =CONCATENATE(E2,"/",H3,"-",E5,"(",F4,")",E6) -> 30/03-А(23) | D2: День | E2: =DAY(TODAY()) -> 30 | V2: В Лице
A3: Дата | B3: =CONCATENATE(E2," ",F3," ",E4,"г.") -> 30 марта 2023г. | D3: Месяц | E3: =MONTH(TODAY()) -> 3 | F3: =IF(E3=1,"января",IF(E3=2,"февраля",IF(E3=3,"марта",IF(E3=4,"апреля",IF(E3=5,"мая",IF(E3=6,"июня",IF(E3=7,"июля",IF(E3=8,"августа",IF(E3=9,"сентября",IF(E3=10,"октября",IF(E3=11,"ноября",IF(E3=12,"декабря")))))))))))) -> марта | H3: =IF(E3=1,"01",IF(E3=2,"02",IF(E3=3,"03",IF(E3=4,"04",IF(E3=5,"05",IF(E3=6,"06",IF(E3=7,"07",IF(E3=8,"08",IF(E3=9,"09",IF(E3=10,"10",IF(E3=11,"11",IF(E3=12,"12")))))))))))) -> 03 | V3: директора | X3: Действующий
A4: Организация | B4: ООО "Эдвако-Инжиниринг" | D4: Год | E4: =YEAR(TODAY()) -> 2023 | F4: =RIGHT(E4,2) -> 23 | V4: генерального директора | X4: Устава
A5: в лице | B5: генерального директора | D5: Буква | E5: А | V5: исполнительного директора | X5: записи в ЕГРН
A6: ФИО директора | B6: Коряжбина Эдуарда Васильевича | D6: Индекс | V6: индивидуального предпринимателя | X6: Свидетельства
A7: Дейсвующий на основании | B7: Устава | V7: управляющего | X7: договора
A8: Свидетельство(Договор) № | V8: управляющего индивидуального предпринимателя | X8: доверенности
A9: Юр.Адрес | B9: 620014, РФ, г. Екатеринбург, ул. Московская, д.11 офис 903 | V9: заместителя директора
A10: ИНН | B10: 6658401387
A11: КПП | B11: 665801001
A12: р/счет | B12: 40702810562130001221
A13: в банке | B13: ПАО КБ «УБРиР»
A14: БИК | B14: 046577795
A15: кор/счет | B15: 30101810900000000795
A16: ОГРН | B16: 1126658000050
A17: Почт адрес | B17: 620014, РФ, г. Екатеринбург, ул. Московская, д.11 офис 903
A18: Адрес доставки | C18: Самовывоз
A19: E-MAIL | B19: ekoryazhbin@mail.ru
A20: Телефон | B20: (+7343) 227-34-77
A22: Город работы | B22: г. Екатеринбург

Sheet Договор аренды лесов Юр
A1: ='Расчет лесов'!C3 -> 210 | B1: =AW41 -> 0
BK2: Вспомогательные значения | BW2: Наименование | BX2: =IF($AW$20="без НДС",реквизиты!C3,реквизиты!G3) -> Универсальная производственно-строительная компания
A3: =CONCATENATE("ДОГОВОР АРЕНДЫ ОБОРУДОВАНИЯ №",ДляДоговора!B2) -> ДОГОВОР АРЕНДЫ ОБОРУДОВАНИЯ №30/03-А(23) | BK3: Срок аренды | BL3: ='Расчет лесов'!C4 -> 30 | BW3: В лице Директора | BX3: =IF($AW$20="без НДС",реквизиты!C4,реквизиты!G4) -> Выборных Андрея Павловича
BW4: Для подписи | BX4: =IF($AW$20="без НДС",реквизиты!C5,реквизиты!G5) -> А.П. Выборных
A5: =ДляДоговора!B22 -> г. Екатеринбург | AK5: =ДляДоговора!B3 -> 30 марта 2023г. | BK5: длина | BL5: ='Расчет лесов'!J3 -> 3 | BW5: ИНН | BX5: =IF($AW$20="без НДС",реквизиты!C6,реквизиты!G6) -> 6670463929
BK6: высота | BL6: ='Расчет лесов'!K3 -> 8 | BW6: КПП | BX6: =IF($AW$20="без НДС",реквизиты!C7,реквизиты!G7) -> 667001001
A7: ="Общество с ограниченной ответственностью «"&BX2&"» (ООО «УПСК»), именуемое в дальнейшем «Арендодатель», в лице директора "&BX3&", действующего на основании Устава, с одной стороны, и "&ДляДоговора!B4&" именуемое в дальнейшем «Арендатор», в лице "&ДляДоговора!B5&" "&ДляДоговора!B6&", действующего на основании "&ДляДоговора!B7&ДляДоговора!B8&", с другой стороны, именуемые вместе «Стороны», а по отдельности «Сторона», заключили настоящий договор (далее - Договор) о нижеследующем." -> Общество с ограниченной ответственностью «Универсальная производственно-строительная компания» (ООО «УПСК»), именуемое в дальнейшем «Арендодатель», в лице директора Выборных Андрея Павловича, действующего на основании Устава, с одной стороны, и ООО "Эдвако-Инжиниринг" именуемое в дальнейшем «Арендатор», в лице генерального директора Коряжбина Эдуарда Васильевича, действующего на основании Устава, с другой стороны, именуемые вместе «Стороны», а по отдельности «Сторона», заключили настоящий договор (далее - Договор) о нижеследующем. | BW7: ОГРН | BX7: =IF($AW$20="без НДС",реквизиты!C8,реквизиты!G8) -> 1186658009042
BL8: =TODAY() -> 45015 | BW8: Юр. адрес | BX8: =IF($AW$20="без НДС",реквизиты!C9,реквизиты!G9) -> 620066, Свердловская область, г. Екатеринбург, ул. Вилонова, стр. 45Л, офис 506,
BL9: =DAY(TODAY()) -> 30 | BM9: -4 | BW9: Почт. Адрес | BX9: =IF($AW$20="без НДС",реквизиты!C10,реквизиты!G10) -> 620066, Свердловская область, г. Екатеринбург, ул. Вилонова, стр. 45Л
BF10: =MONTH(TODAY()) -> 3 | BL10: =YEAR(TODAY()) -> 2023 | BW10: Р/счет | BX10: =IF($AW$20="без НДС",реквизиты!C11,реквизиты!G11) -> 40702810816540041503
BL11: =IF(BF10=1,"01",IF(BF10=2,"02",IF(BF10=3,"03",IF(BF10=4,"04",IF(BF10=5,"05",IF(BF10=6,"06",IF(BF10=7,"07",IF(BF10=8,"08",IF(BF10=9,"09",IF(BF10=10,"10",IF(BF10=11,"11",IF(BF10=12,"12")))))))))))) -> 03 | BW11: в банке | BX11: =IF($AW$20="без НДС",реквизиты!C12,реквизиты!G12) -> УРАЛЬСКИЙ БАНК ПАО СБЕРБАНК
BW12: Кор. Счет | BX12: =IF($AW$20="без НДС",реквизиты!C13,реквизиты!G13) -> 30101810500000000674
A13: 1. ПРЕДМЕТ ДОГОВОРА | BL13: =IF(BF10=1,"января",IF(BF10=2,"февраля",IF(BF10=3,"марта",IF(BF10=4,"апреля",IF(BF10=5,"мая",IF(BF10=6,"июня",IF(BF10=7,"июля",IF(BF10=8,"августа",IF(BF10=9,"сентября",IF(BF10=10,"октября",IF(BF10=11,"ноября",IF(BF10=12,"декабря")))))))))))) -> марта | BW13: БИК | BX13: =IF($AW$20="без НДС",реквизиты!C14,реквизиты!G14) -> 046577674
A14: 1.1. В порядке и на условиях настоящего Договора Арендодатель обязуется передать за плату во временное пользование (аренду) Арендатору имущество (далее по тексту «имущество» или «Оборудование») согласно Спецификации (Приложение №1 к настоящему Договору)
A17: 1.2. Арендуемое имущество передается Арендатору для осуществления предпринимательской деятельности.
A18: 1.3. Перечень, количество, стоимость передаваемого в аренду Оборудования, срок его аренды согласовывается сторонами в Спецификации, являющейся неотъемлемой частью настоящего Договора (Приложение №1 к Договору). | AV18: Объем | AW18: =CONCATENATE('Расчет лесов'!L12,'Расчет лесов'!M12) -> 24м2
A20: 2. ПОРЯДОК ПЕРЕДАЧИ, ТРАНСПОРТИРОВКИ И ВОЗВРАТА АРЕНДУЕМОГО ИМУЩЕСТВА | AV20: Налогообложение | AW20: с НДС 20%
A21: 2.1. Арендуемое имущество передается в состоянии, пригодном для немедленного и непосредственного осуществления Арендатором своей деятельности с его использованием. | AV21: сумма в сутки | AW21: =SUBSTITUTE(PROPER(INDEX(n_4,MID(TEXT(A1,n0),1,1)+1)&INDEX(n0x,MID(TEXT(A1,n0),2,1)+1,MID(TEXT(A1,n0),3,1)+1)&IF(-MID(TEXT(A1,n0),1,3),"миллиард"&VLOOKUP(MID(TEXT(A1,n0),3,1)*AND(MID(TEXT(A1,n0),2,1)-1),мил,2),"")&INDEX(n_4,MID(TEXT(A1,n0),4,1)+1)&INDEX(n0x,MID(TEXT(A1,n0),5,1)+1,MID(TEXT(A1,n0),6,1)+1)&IF(-MID(TEXT(A1,n0),4,3),"миллион"&VLOOKUP(MID(TEXT(A1,n0),6,1)*AND(MID(TEXT(A1,n0),5,1)-1),мил,2),"")&INDEX(n_4,MID(TEXT(A1,n0),7,1)+1)&INDEX(n1x,MID(TEXT(A1,n0),8,1)+1,MID(TEXT(A1,n0),9,1)+1)&IF(-MID(TEXT(A1,n0),7,3),VLOOKUP(MID(TEXT(A1,n0),9,1)*AND(MID(TEXT(A1,n0),8,1)-1),тыс,2),"")&INDEX(n_4,MID(TEXT(A1,n0),10,1)+1)&INDEX(n0x,MID(TEXT(A1,n0),11,1)+1,MID(TEXT(A1,n0),12,1)+1)),"z"," ")&IF(TRUNC(TEXT(A1,n0)),"","Ноль ")&"рубл"&VLOOKUP(MOD(MAX(MOD(MID(TEXT(A1,n0),11,2)-11,100),9),10),{0,"ь ";1,"я ";4,"ей "},2)&RIGHT(TEXT(A1,n0),2)&" копе"&VLOOKUP(MOD(MAX(MOD(RIGHT(TEXT(A1,n0),2)-11,100),9),10),{0,"йка";1,"йки";4,"ек"},2) -> Двести десять рублей 00 копеек | AX21: =SUBSTITUTE(PROPER(INDEX(n_4,MID(TEXT(B1,n0),1,1)+1)&INDEX(n0x,MID(TEXT(B1,n0),2,1)+1,MID(TEXT(B1,n0),3,1)+1)&IF(-MID(TEXT(B1,n0),1,3),"миллиард"&VLOOKUP(MID(TEXT(B1,n0),3,1)*AND(MID(TEXT(B1,n0),2,1)-1),мил,2),"")&INDEX(n_4,MID(TEXT(B1,n0),4,1)+1)&INDEX(n0x,MID(TEXT(B1,n0),5,1)+1,MID(TEXT(B1,n0),6,1)+1)&IF(-MID(TEXT(B1,n0),4,3),"миллион"&VLOOKUP(MID(TEXT(B1,n0),6,1)*AND(MID(TEXT(B1,n0),5,1)-1),мил,2),"")&INDEX(n_4,MID(TEXT(B1,n0),7,1)+1)&INDEX(n1x,MID(TEXT(B1,n0),8,1)+1,MID(TEXT(B1,n0),9,1)+1)&IF(-MID(TEXT(B1,n0),7,3),VLOOKUP(MID(TEXT(B1,n0),9,1)*AND(MID(TEXT(B1,n0),8,1)-1),тыс,2),"")&INDEX(n_4,MID(TEXT(B1,n0),10,1)+1)&INDEX(n0x,MID(TEXT(B1,n0),11,1)+1,MID(TEXT(B1,n0),12,1)+1)),"z"," ")&IF(TRUNC(TEXT(B1,n0)),"","Ноль ")&"рубл"&VLOOKUP(MOD(MAX(MOD(MID(TEXT(B1,n0),11,2)-11,100),9),10),{0,"ь ";1,"я ";4,"ей "},2)&RIGHT(TEXT(B1,n0),2)&" копе"&VLOOKUP(MOD(MAX(MOD(RIGHT(TEXT(B1,n0),2)-11,100),9),10),{0,"йка";1,"йки";4,"ек"},2) -> Ноль рублей 00 копеек
A22: 2.2. Арендуемое имущество передается Арендодателем Арендатору по Акту приема-передачи арендованного имущества (Приложение № 2 к настоящему Договору).
A23: 2.3. Транспортировка и погрузо-разгрузочные работы арендованного имущества со склада Арендодателя до объекта Арендатора и по истечении срока аренды на склад Арендодателя осуществляется за счет Арендатора.
A24: Прием и передача арендованного оборудования, производится в рабочие дни понедельник – пятница (кроме праздничных дней) с 09:00 до 17:00 часов если иное не согласованно сторонами.
A25: 2.4. По окончании срока аренды Сторонами или их представителями производится осмотр арендованного имущества с целью выявления дефектов и повреждений, не предусмотренных условиями нормальной эксплуатации и износа, после чего Стороны (их представители) составляют и подписывают акт приема-передачи (Возврата) арендованного имущества от Арендатора.
A26: Если в ходе осмотра выявлены дефекты и повреждения Стороны или их представители заносят характер дефектов и повреждений в акт приема-передачи (возврата) оборудования, который является основанием для оплаты Арендатором стоимости обслуживания и ремонта арендованного имущества в установленном настоящим Договором размере.
A27: 2.5. Арендодатель не производит приемку и передачу оборудования в случаях: 2.5.1. Отсутствия доверенности у представителя Арендатора;
A28: 2.5.2. Предъявления доверенности срок действия которой истек, или доверенности оформленной ненадлежащим образом (ошибки, поправки, исправления);
A29: 2.5.3. Отсутствия у представителя документа, удостоверяющего его личность и указанного в доверенности.
A30: 2.6. При наступлении обстоятельств, предусмотренных п. 2.5. Договора Арендатор обязан возместить все расходы, понесенные Арендодателем, связанные с организацией приемки-передачи Оборудования (погрузочно-разгрузочные работы, транспортные расходы).
A31: 2.7. Оборудование должно быть возвращено Арендодателю в том состоянии и комплектности, в котором было передано Арендатору.
A32: 2.8. 2.8. Возврат Оборудования не освобождает Арендатора от исполнения обязательств по оплате всех причитающихся в связи пользованием Оборудованием платежей в соответствии с условиями Договора.
A33: 2.9. Требования к возврату оборудования регламентируются, разделом 8 настоящего Договора.
... A61: 4.1. Арендатор, в течение 3 (Трех) рабочих дней с момента подписания Договора, уплачивает Арендодателю обеспечительный взнос в размере согласованном Сторонами в Спецификации на арендуемое имущество, а так же авансом арендную плату согласно Приложению №1 к настоящему Договору.
A62: 4.2. Арендная плата подлежит начислению с даты передачи Имущества Арендатору по Акту приема -передачи, включая день когда Имущество было передано, по день возврата этого Имущества Арендатору. | AU62: ='Расчет лесов'!C4 -> 30 | AV62: аванс за … дней
A63: 4.3. В случае продления срока аренды, Арендатор, в течение 3 (Трех) рабочих дней до момента окончания Срока аренды, оплачивает Стоимость продления аренды авансом в размере 100%.
A64: 4.4. Арендодатель, в течение 10 (десяти) рабочих дней с момента подписания Акта приема – передачи (возврата) оборудования и получения от Арендатора оригинала письма о возврате обеспечительного взноса, возвращает Арендатору обеспечительный взнос или его остаток.
A65: 4.5. Арендодатель имеет право самостоятельно в одностороннем порядке производить вычеты из обеспечительного взноса, в случае, если Арендатор не оплачивает в течение 5 (Пяти) рабочих дней с момента его уведомления, следующие платежи:
A66: 4.5.1. Арендной платы при продления аренды, арендной платы за время просрочки возврата оборудования;
A67: 4.5.2. Стоимость утраченного оборудования.
A68: 4.5.3. Стоимость ремонта / обслуживания оборудования.
A69: 4.5.4. Сумму расходов, связанных с досрочным расторжением Договора и вывозом оборудования с объекта (транспортные расходы, расходы по погрузке и разгрузке Оборудования, стоимость утраченного оборудования, ремонт/обслуживание оборудования и т.д.).
A70: 4.5.5. Суммы штрафных санкций, неустоек (пени) предусмотренных Договором.
...

Sheet Счет Юр леса
B1: Внимание! Оплата данного счета означает согласие с условиями поставки товара. Уведомление об оплате обязательно, в противном случае не гарантируется наличие товара на складе. Товар отпускается по факту прихода денег на р/с Поставщика, самовывозом, при наличии доверенности и паспорта.
AX2: № СЧЕТА | AY2: 660
A3: =AH26 -> 9400 | AX3: Всего наименований | AY3: 4
B5: ='Договор аренды лесов Юр'!BX11 -> УРАЛЬСКИЙ БАНК ПАО СБЕРБАНК | T5: БИК | X5: ='Договор аренды лесов Юр'!BX13 -> 046577674 | AX5: день | AY5: =DAY(TODAY()) -> 30
T6: Сч. № | X6: ='Договор аренды лесов Юр'!BX12 -> 30101810500000000674 | AX6: месяц | AY6: =IF(BF10=1,"января",IF(BF10=2,"февраля",IF(BF10=3,"марта",IF(BF10=4,"апреля",IF(BF10=5,"мая",IF(BF10=6,"июня",IF(BF10=7,"июля",IF(BF10=8,"августа",IF(BF10=9,"сентября",IF(BF10=10,"октября",IF(BF10=11,"ноября",IF(BF10=12,"декабря")))))))))))) -> марта
B7: Банк получателя | AX7: год | AY7: =YEAR(TODAY()) -> 2023
B8: ИНН | D8: ='Договор аренды лесов Юр'!BX5 -> 6670463929 | K8: КПП | M8: ='Договор аренды лесов Юр'!BX6 -> 667001001 | T8: Сч. № | X8: ='Договор аренды лесов Юр'!BX10 -> 40702810816540041503
B9: ООО"УПСК"
BF10: =MONTH(TODAY()) -> 3
B11: Получатель
B13: =CONCATENATE("Счет на оплату № ",AY2," от ",AY5," ",AY6," ",AY7,"г.") -> Счет на оплату № 660 от 30 марта 2023г.
B17: Поставщик: | F17: =CONCATENATE("ООО «УПСК», ИНН ",D8,", КПП ",M8,", ",реквизиты!G9," тел.8(343)2068882") -> ООО «УПСК», ИНН 6670463929, КПП 667001001, 620066, Свердловская область, г. Екатеринбург, ул. Вилонова, стр. 45Л, офис 506, тел.8(343)2068882
B19: Покупатель: | F19: =CONCATENATE(ДляДоговора!B4,", ИНН ",ДляДоговора!B10,", КПП ",ДляДоговора!B11,", Адрес: ",ДляДоговора!B9) -> ООО "Эдвако-Инжиниринг", ИНН 6658401387, КПП 665801001, Адрес: 620014, РФ, г. Екатеринбург, ул. Московская, д.11 офис 903
B21: № | D21: Товары (работы, услуги) | U21: Кол-во | Y21: Ед. | AB21: Цена | AH21: Сумма
B22: 1 | D22: =CONCATENATE("Оплата по договору № ",ДляДоговора!B2," от ",ДляДоговора!B3) -> Оплата по договору № 30/03-А(23) от 30 марта 2023г. | U22: ='Расчет лесов'!C4 -> 30 | Y22: сутки | AB22: ='Расчет лесов'!C3 -> 210 | AH22: =U22*AB22 -> 6300
B23: 2 | D23: Залоговая стоимость оборудования | U23: =IF(AY3=1,0,1) -> 1 | Y23: шт | AB23: ='Расчет лесов'!D17 -> 3100 | AH23: =U23*AB23 -> 3100
B24: 3 | D24: Доставка | U24: =IF(AY3=1,0,IF(AY3=2,0,1)) -> 1 | Y24: шт | AB24: ='Расчет лесов'!D18 -> 0 | AH24: =U24*AB24 -> 0
B25: 4 | D25: Доставка | U25: =IF(AY3=1,0,IF(AY3=2,0,IF(AY3=3,0,1))) -> 1 | Y25: шт | AB25: ='Расчет лесов'!D19 -> 0 | AH25: =U25*AB25 -> 0
AG26: Итого: | AH26: =SUM(AH22:AL25) -> 9400
AG27: В том числе НДС 20%: | AH27: =IF(D8=6670428868,AX28,AX27) -> 1050 | AX27: =(AH26-AH23)*20/120 -> 1050
AG28: Всего к оплате: | AH28: =AH26 -> 9400 | AX28: -
B29: =CONCATENATE("Всего наименований ",AY3," на сумму ",AH28,",00 руб.") -> Всего наименований 4 на сумму 9400,00 руб.
B30: =SUBSTITUTE(PROPER(INDEX(n_4,MID(TEXT(A3,n0),1,1)+1)&INDEX(n0x,MID(TEXT(A3,n0),2,1)+1,MID(TEXT(A3,n0),3,1)+1)&IF(-MID(TEXT(A3,n0),1,3),"миллиард"&VLOOKUP(MID(TEXT(A3,n0),3,1)*AND(MID(TEXT(A3,n0),2,1)-1),мил,2),"")&INDEX(n_4,MID(TEXT(A3,n0),4,1)+1)&INDEX(n0x,MID(TEXT(A3,n0),5,1)+1,MID(TEXT(A3,n0),6,1)+1)&IF(-MID(TEXT(A3,n0),4,3),"миллион"&VLOOKUP(MID(TEXT(A3,n0),6,1)*AND(MID(TEXT(A3,n0),5,1)-1),мил,2),"")&INDEX(n_4,MID(TEXT(A3,n0),7,1)+1)&INDEX(n1x,MID(TEXT(A3,n0),8,1)+1,MID(TEXT(A3,n0),9,1)+1)&IF(-MID(TEXT(A3,n0),7,3),VLOOKUP(MID(TEXT(A3,n0),9,1)*AND(MID(TEXT(A3,n0),8,1)-1),тыс,2),"")&INDEX(n_4,MID(TEXT(A3,n0),10,1)+1)&INDEX(n0x,MID(TEXT(A3,n0),11,1)+1,MID(TEXT(A3,n0),12,1)+1)),"z"," ")&IF(TRUNC(TEXT(A3,n0)),"","Ноль ")&"рубл"&VLOOKUP(MOD(MAX(MOD(MID(TEXT(A3,n0),11,2)-11,100),9),10),{0,"ь ";1,"я ";4,"ей "},2)&RIGHT(TEXT(A3,n0),2)&" копе"&VLOOKUP(MOD(MAX(MOD(RIGHT(TEXT(A3,n0),2)-11,100),9),10),{0,"йка";1,"йки";4,"ек"},2) -> Девять тысяч четыреста рублей 00 копеек
AX32: ='Договор аренды лесов Юр'!BX4 -> А.П. Выборных
B33: Руководитель | K33: =AX32 -> А.П. Выборных | V33: Бухгалтер | AE33: =AX32 -> А.П. Выборных
C36: Важно! Перед оплатой счета необходимо связаться с менеджером для уточнения наличия
C37: продукции на складе.

Sheet Договор аренды тур Юр
A1: ='Вышки туры'!B5 -> 156
BK2: Вспомогательные значения | BW2: Наименование | BX2: =IF($AW$20="без НДС",реквизиты!C3,реквизиты!G3) -> Универсальная производственно-строительная компания
A3: =CONCATENATE("ДОГОВОР АРЕНДЫ ОБОРУДОВАНИЯ №",ДляДоговора!B2) -> ДОГОВОР АРЕНДЫ ОБОРУДОВАНИЯ №30/03-А(23) | BK3: Срок аренды | BL3: ='Вышки туры'!G2 -> 30 | BW3: В лице Директора | BX3: =IF($AW$20="без НДС",реквизиты!C4,реквизиты!G4) -> Выборных Андрея Павловича
BW4: Для подписи | BX4: =IF($AW$20="без НДС",реквизиты!C5,реквизиты!G5) -> А.П. Выборных
A5: =ДляДоговора!B22 -> г. Екатеринбург | AK5: =ДляДоговора!B3 -> 30 марта 2023г. | BW5: ИНН | BX5: =IF($AW$20="без НДС",реквизиты!C6,реквизиты!G6) -> 6670463929
BW6: КПП | BX6: =IF($AW$20="без НДС",реквизиты!C7,реквизиты!G7) -> 667001001
